<?xml version="1.0" encoding="UTF-8"?>
<!-- Generated by org.testng.reporters.JUnitReportReporter -->
<testsuite hostname="DESKTOP-EA7R36R" name="testcases.EnterCItyName_Testcases" tests="6" failures="6" timestamp="3 Apr 2019 07:47:01 GMT" time="64.289" errors="0">
  <testcase name="Login_process" time="12.036" classname="testcases.EnterCItyName_Testcases">
    <failure type="java.lang.AssertionError" message="The following asserts failed:
	Verifying the maximum wind speed displayed in ui for the day 2 expected [4] but found [1],
	Verifying the maximum wind speed displayed in ui for the day 3 expected [5] but found [2],
	Verifying the maximum wind speed displayed in ui for the day 4 expected [8] but found [5],
	Verifying the maximum pressure for the day 4 expected [1005] but found [999],
	Verifying the maximum wind speed displayed in ui for the day 5 expected [9] but found [8]">
      <![CDATA[java.lang.AssertionError: The following asserts failed:
	Verifying the maximum wind speed displayed in ui for the day 2 expected [4] but found [1],
	Verifying the maximum wind speed displayed in ui for the day 3 expected [5] but found [2],
	Verifying the maximum wind speed displayed in ui for the day 4 expected [8] but found [5],
	Verifying the maximum pressure for the day 4 expected [1005] but found [999],
	Verifying the maximum wind speed displayed in ui for the day 5 expected [9] but found [8]
	at org.testng.asserts.SoftAssert.assertAll(SoftAssert.java:43)
	at Page_Objects.EnterCityName_Objects.verifyWeatherForeCastForAllDays(EnterCityName_Objects.java:183)
	at testcases.EnterCItyName_Testcases.Login_process(EnterCItyName_Testcases.java:44)
	at sun.reflect.NativeMethodAccessorImpl.invoke0(Native Method)
	at sun.reflect.NativeMethodAccessorImpl.invoke(Unknown Source)
	at sun.reflect.DelegatingMethodAccessorImpl.invoke(Unknown Source)
	at java.lang.reflect.Method.invoke(Unknown Source)
	at org.testng.internal.MethodInvocationHelper.invokeMethod(MethodInvocationHelper.java:86)
	at org.testng.internal.Invoker.invokeMethod(Invoker.java:643)
	at org.testng.internal.Invoker.invokeTestMethod(Invoker.java:820)
	at org.testng.internal.Invoker.invokeTestMethods(Invoker.java:1128)
	at org.testng.internal.TestMethodWorker.invokeTestMethods(TestMethodWorker.java:129)
	at org.testng.internal.TestMethodWorker.run(TestMethodWorker.java:112)
	at org.testng.TestRunner.privateRun(TestRunner.java:782)
	at org.testng.TestRunner.run(TestRunner.java:632)
	at org.testng.SuiteRunner.runTest(SuiteRunner.java:366)
	at org.testng.SuiteRunner.runSequentially(SuiteRunner.java:361)
	at org.testng.SuiteRunner.privateRun(SuiteRunner.java:319)
	at org.testng.SuiteRunner.run(SuiteRunner.java:268)
	at org.testng.SuiteRunnerWorker.runSuite(SuiteRunnerWorker.java:52)
	at org.testng.SuiteRunnerWorker.run(SuiteRunnerWorker.java:86)
	at org.testng.TestNG.runSuitesSequentially(TestNG.java:1244)
	at org.testng.TestNG.runSuitesLocally(TestNG.java:1169)
	at org.testng.TestNG.run(TestNG.java:1064)
	at org.testng.remote.AbstractRemoteTestNG.run(AbstractRemoteTestNG.java:115)
	at org.testng.remote.RemoteTestNG.initAndRun(RemoteTestNG.java:251)
	at org.testng.remote.RemoteTestNG.main(RemoteTestNG.java:77)
]]>
    </failure>
  </testcase> <!-- Login_process -->
  <testcase name="Login_process" time="8.817" classname="testcases.EnterCItyName_Testcases">
    <failure type="java.lang.AssertionError" message="The following asserts failed:
	Verifying the maximum wind speed displayed in ui for the day 2 expected [5] but found [1],
	Verifying the maximum wind speed displayed in ui for the day 3 expected [8] but found [3],
	Verifying the maximum wind speed displayed in ui for the day 4 expected [9] but found [6],
	Verifying the maximum pressure for the day 4 expected [1005] but found [999],
	Verifying the maximum wind speed displayed in ui for the day 5 expected [11] but found [10]">
      <![CDATA[java.lang.AssertionError: The following asserts failed:
	Verifying the maximum wind speed displayed in ui for the day 2 expected [5] but found [1],
	Verifying the maximum wind speed displayed in ui for the day 3 expected [8] but found [3],
	Verifying the maximum wind speed displayed in ui for the day 4 expected [9] but found [6],
	Verifying the maximum pressure for the day 4 expected [1005] but found [999],
	Verifying the maximum wind speed displayed in ui for the day 5 expected [11] but found [10]
	at org.testng.asserts.SoftAssert.assertAll(SoftAssert.java:43)
	at Page_Objects.EnterCityName_Objects.verifyWeatherForeCastForAllDays(EnterCityName_Objects.java:183)
	at testcases.EnterCItyName_Testcases.Login_process(EnterCItyName_Testcases.java:44)
	at sun.reflect.NativeMethodAccessorImpl.invoke0(Native Method)
	at sun.reflect.NativeMethodAccessorImpl.invoke(Unknown Source)
	at sun.reflect.DelegatingMethodAccessorImpl.invoke(Unknown Source)
	at java.lang.reflect.Method.invoke(Unknown Source)
	at org.testng.internal.MethodInvocationHelper.invokeMethod(MethodInvocationHelper.java:86)
	at org.testng.internal.Invoker.invokeMethod(Invoker.java:643)
	at org.testng.internal.Invoker.invokeTestMethod(Invoker.java:820)
	at org.testng.internal.Invoker.invokeTestMethods(Invoker.java:1128)
	at org.testng.internal.TestMethodWorker.invokeTestMethods(TestMethodWorker.java:129)
	at org.testng.internal.TestMethodWorker.run(TestMethodWorker.java:112)
	at org.testng.TestRunner.privateRun(TestRunner.java:782)
	at org.testng.TestRunner.run(TestRunner.java:632)
	at org.testng.SuiteRunner.runTest(SuiteRunner.java:366)
	at org.testng.SuiteRunner.runSequentially(SuiteRunner.java:361)
	at org.testng.SuiteRunner.privateRun(SuiteRunner.java:319)
	at org.testng.SuiteRunner.run(SuiteRunner.java:268)
	at org.testng.SuiteRunnerWorker.runSuite(SuiteRunnerWorker.java:52)
	at org.testng.SuiteRunnerWorker.run(SuiteRunnerWorker.java:86)
	at org.testng.TestNG.runSuitesSequentially(TestNG.java:1244)
	at org.testng.TestNG.runSuitesLocally(TestNG.java:1169)
	at org.testng.TestNG.run(TestNG.java:1064)
	at org.testng.remote.AbstractRemoteTestNG.run(AbstractRemoteTestNG.java:115)
	at org.testng.remote.RemoteTestNG.initAndRun(RemoteTestNG.java:251)
	at org.testng.remote.RemoteTestNG.main(RemoteTestNG.java:77)
]]>
    </failure>
  </testcase> <!-- Login_process -->
  <testcase name="Login_process" time="10.098" classname="testcases.EnterCItyName_Testcases">
    <failure type="java.lang.AssertionError" message="The following asserts failed:
	Verifying the maximum wind speed displayed in ui for the day 2 expected [5] but found [2],
	Verifying the maximum wind speed displayed in ui for the day 3 expected [7] but found [3],
	Verifying the maximum wind speed displayed in ui for the day 4 expected [9] but found [7],
	Verifying the maximum pressure for the day 4 expected [1019] but found [1014]">
      <![CDATA[java.lang.AssertionError: The following asserts failed:
	Verifying the maximum wind speed displayed in ui for the day 2 expected [5] but found [2],
	Verifying the maximum wind speed displayed in ui for the day 3 expected [7] but found [3],
	Verifying the maximum wind speed displayed in ui for the day 4 expected [9] but found [7],
	Verifying the maximum pressure for the day 4 expected [1019] but found [1014]
	at org.testng.asserts.SoftAssert.assertAll(SoftAssert.java:43)
	at Page_Objects.EnterCityName_Objects.verifyWeatherForeCastForAllDays(EnterCityName_Objects.java:183)
	at testcases.EnterCItyName_Testcases.Login_process(EnterCItyName_Testcases.java:44)
	at sun.reflect.NativeMethodAccessorImpl.invoke0(Native Method)
	at sun.reflect.NativeMethodAccessorImpl.invoke(Unknown Source)
	at sun.reflect.DelegatingMethodAccessorImpl.invoke(Unknown Source)
	at java.lang.reflect.Method.invoke(Unknown Source)
	at org.testng.internal.MethodInvocationHelper.invokeMethod(MethodInvocationHelper.java:86)
	at org.testng.internal.Invoker.invokeMethod(Invoker.java:643)
	at org.testng.internal.Invoker.invokeTestMethod(Invoker.java:820)
	at org.testng.internal.Invoker.invokeTestMethods(Invoker.java:1128)
	at org.testng.internal.TestMethodWorker.invokeTestMethods(TestMethodWorker.java:129)
	at org.testng.internal.TestMethodWorker.run(TestMethodWorker.java:112)
	at org.testng.TestRunner.privateRun(TestRunner.java:782)
	at org.testng.TestRunner.run(TestRunner.java:632)
	at org.testng.SuiteRunner.runTest(SuiteRunner.java:366)
	at org.testng.SuiteRunner.runSequentially(SuiteRunner.java:361)
	at org.testng.SuiteRunner.privateRun(SuiteRunner.java:319)
	at org.testng.SuiteRunner.run(SuiteRunner.java:268)
	at org.testng.SuiteRunnerWorker.runSuite(SuiteRunnerWorker.java:52)
	at org.testng.SuiteRunnerWorker.run(SuiteRunnerWorker.java:86)
	at org.testng.TestNG.runSuitesSequentially(TestNG.java:1244)
	at org.testng.TestNG.runSuitesLocally(TestNG.java:1169)
	at org.testng.TestNG.run(TestNG.java:1064)
	at org.testng.remote.AbstractRemoteTestNG.run(AbstractRemoteTestNG.java:115)
	at org.testng.remote.RemoteTestNG.initAndRun(RemoteTestNG.java:251)
	at org.testng.remote.RemoteTestNG.main(RemoteTestNG.java:77)
]]>
    </failure>
  </testcase> <!-- Login_process -->
  <testcase name="Login_process" time="12.599" classname="testcases.EnterCItyName_Testcases">
    <failure type="java.lang.AssertionError" message="The following asserts failed:
	Verifying the maximum wind speed displayed in ui for the day 1 expected [4] but found [3],
	Verifying the maximum wind speed displayed in ui for the day 2 expected [7] but found [2],
	Verifying the maximum wind speed displayed in ui for the day 3 expected [8] but found [5],
	Verifying the maximum wind speed displayed in ui for the day 4 expected [9] but found [6],
	Verifying the maximum pressure for the day 4 expected [1011] but found [1006]">
      <![CDATA[java.lang.AssertionError: The following asserts failed:
	Verifying the maximum wind speed displayed in ui for the day 1 expected [4] but found [3],
	Verifying the maximum wind speed displayed in ui for the day 2 expected [7] but found [2],
	Verifying the maximum wind speed displayed in ui for the day 3 expected [8] but found [5],
	Verifying the maximum wind speed displayed in ui for the day 4 expected [9] but found [6],
	Verifying the maximum pressure for the day 4 expected [1011] but found [1006]
	at org.testng.asserts.SoftAssert.assertAll(SoftAssert.java:43)
	at Page_Objects.EnterCityName_Objects.verifyWeatherForeCastForAllDays(EnterCityName_Objects.java:183)
	at testcases.EnterCItyName_Testcases.Login_process(EnterCItyName_Testcases.java:44)
	at sun.reflect.NativeMethodAccessorImpl.invoke0(Native Method)
	at sun.reflect.NativeMethodAccessorImpl.invoke(Unknown Source)
	at sun.reflect.DelegatingMethodAccessorImpl.invoke(Unknown Source)
	at java.lang.reflect.Method.invoke(Unknown Source)
	at org.testng.internal.MethodInvocationHelper.invokeMethod(MethodInvocationHelper.java:86)
	at org.testng.internal.Invoker.invokeMethod(Invoker.java:643)
	at org.testng.internal.Invoker.invokeTestMethod(Invoker.java:820)
	at org.testng.internal.Invoker.invokeTestMethods(Invoker.java:1128)
	at org.testng.internal.TestMethodWorker.invokeTestMethods(TestMethodWorker.java:129)
	at org.testng.internal.TestMethodWorker.run(TestMethodWorker.java:112)
	at org.testng.TestRunner.privateRun(TestRunner.java:782)
	at org.testng.TestRunner.run(TestRunner.java:632)
	at org.testng.SuiteRunner.runTest(SuiteRunner.java:366)
	at org.testng.SuiteRunner.runSequentially(SuiteRunner.java:361)
	at org.testng.SuiteRunner.privateRun(SuiteRunner.java:319)
	at org.testng.SuiteRunner.run(SuiteRunner.java:268)
	at org.testng.SuiteRunnerWorker.runSuite(SuiteRunnerWorker.java:52)
	at org.testng.SuiteRunnerWorker.run(SuiteRunnerWorker.java:86)
	at org.testng.TestNG.runSuitesSequentially(TestNG.java:1244)
	at org.testng.TestNG.runSuitesLocally(TestNG.java:1169)
	at org.testng.TestNG.run(TestNG.java:1064)
	at org.testng.remote.AbstractRemoteTestNG.run(AbstractRemoteTestNG.java:115)
	at org.testng.remote.RemoteTestNG.initAndRun(RemoteTestNG.java:251)
	at org.testng.remote.RemoteTestNG.main(RemoteTestNG.java:77)
]]>
    </failure>
  </testcase> <!-- Login_process -->
  <testcase name="Login_process" time="9.922" classname="testcases.EnterCItyName_Testcases">
    <failure type="java.lang.AssertionError" message="The following asserts failed:
	Verifying the maximum wind speed displayed in ui for the day 2 expected [3] but found [1],
	Verifying the maximum wind speed displayed in ui for the day 3 expected [4] but found [2],
	Verifying the maximum wind speed displayed in ui for the day 4 expected [6] but found [4],
	Verifying the maximum pressure for the day 4 expected [987] but found [982],
	Verifying the maximum wind speed displayed in ui for the day 5 expected [7] but found [6]">
      <![CDATA[java.lang.AssertionError: The following asserts failed:
	Verifying the maximum wind speed displayed in ui for the day 2 expected [3] but found [1],
	Verifying the maximum wind speed displayed in ui for the day 3 expected [4] but found [2],
	Verifying the maximum wind speed displayed in ui for the day 4 expected [6] but found [4],
	Verifying the maximum pressure for the day 4 expected [987] but found [982],
	Verifying the maximum wind speed displayed in ui for the day 5 expected [7] but found [6]
	at org.testng.asserts.SoftAssert.assertAll(SoftAssert.java:43)
	at Page_Objects.EnterCityName_Objects.verifyWeatherForeCastForAllDays(EnterCityName_Objects.java:183)
	at testcases.EnterCItyName_Testcases.Login_process(EnterCItyName_Testcases.java:44)
	at sun.reflect.NativeMethodAccessorImpl.invoke0(Native Method)
	at sun.reflect.NativeMethodAccessorImpl.invoke(Unknown Source)
	at sun.reflect.DelegatingMethodAccessorImpl.invoke(Unknown Source)
	at java.lang.reflect.Method.invoke(Unknown Source)
	at org.testng.internal.MethodInvocationHelper.invokeMethod(MethodInvocationHelper.java:86)
	at org.testng.internal.Invoker.invokeMethod(Invoker.java:643)
	at org.testng.internal.Invoker.invokeTestMethod(Invoker.java:820)
	at org.testng.internal.Invoker.invokeTestMethods(Invoker.java:1128)
	at org.testng.internal.TestMethodWorker.invokeTestMethods(TestMethodWorker.java:129)
	at org.testng.internal.TestMethodWorker.run(TestMethodWorker.java:112)
	at org.testng.TestRunner.privateRun(TestRunner.java:782)
	at org.testng.TestRunner.run(TestRunner.java:632)
	at org.testng.SuiteRunner.runTest(SuiteRunner.java:366)
	at org.testng.SuiteRunner.runSequentially(SuiteRunner.java:361)
	at org.testng.SuiteRunner.privateRun(SuiteRunner.java:319)
	at org.testng.SuiteRunner.run(SuiteRunner.java:268)
	at org.testng.SuiteRunnerWorker.runSuite(SuiteRunnerWorker.java:52)
	at org.testng.SuiteRunnerWorker.run(SuiteRunnerWorker.java:86)
	at org.testng.TestNG.runSuitesSequentially(TestNG.java:1244)
	at org.testng.TestNG.runSuitesLocally(TestNG.java:1169)
	at org.testng.TestNG.run(TestNG.java:1064)
	at org.testng.remote.AbstractRemoteTestNG.run(AbstractRemoteTestNG.java:115)
	at org.testng.remote.RemoteTestNG.initAndRun(RemoteTestNG.java:251)
	at org.testng.remote.RemoteTestNG.main(RemoteTestNG.java:77)
]]>
    </failure>
  </testcase> <!-- Login_process -->
  <testcase name="Login_process" time="10.817" classname="testcases.EnterCItyName_Testcases">
    <failure type="java.lang.AssertionError" message="The following asserts failed:
	Verifying the maximum wind speed displayed in ui for the day 2 expected [5] but found [2],
	Verifying the maximum wind speed displayed in ui for the day 3 expected [6] but found [3],
	Verifying the maximum wind speed displayed in ui for the day 4 expected [10] but found [6],
	Verifying the maximum pressure for the day 4 expected [1011] but found [1006],
	Verifying the maximum wind speed displayed in ui for the day 5 expected [11] but found [10]">
      <![CDATA[java.lang.AssertionError: The following asserts failed:
	Verifying the maximum wind speed displayed in ui for the day 2 expected [5] but found [2],
	Verifying the maximum wind speed displayed in ui for the day 3 expected [6] but found [3],
	Verifying the maximum wind speed displayed in ui for the day 4 expected [10] but found [6],
	Verifying the maximum pressure for the day 4 expected [1011] but found [1006],
	Verifying the maximum wind speed displayed in ui for the day 5 expected [11] but found [10]
	at org.testng.asserts.SoftAssert.assertAll(SoftAssert.java:43)
	at Page_Objects.EnterCityName_Objects.verifyWeatherForeCastForAllDays(EnterCityName_Objects.java:183)
	at testcases.EnterCItyName_Testcases.Login_process(EnterCItyName_Testcases.java:44)
	at sun.reflect.NativeMethodAccessorImpl.invoke0(Native Method)
	at sun.reflect.NativeMethodAccessorImpl.invoke(Unknown Source)
	at sun.reflect.DelegatingMethodAccessorImpl.invoke(Unknown Source)
	at java.lang.reflect.Method.invoke(Unknown Source)
	at org.testng.internal.MethodInvocationHelper.invokeMethod(MethodInvocationHelper.java:86)
	at org.testng.internal.Invoker.invokeMethod(Invoker.java:643)
	at org.testng.internal.Invoker.invokeTestMethod(Invoker.java:820)
	at org.testng.internal.Invoker.invokeTestMethods(Invoker.java:1128)
	at org.testng.internal.TestMethodWorker.invokeTestMethods(TestMethodWorker.java:129)
	at org.testng.internal.TestMethodWorker.run(TestMethodWorker.java:112)
	at org.testng.TestRunner.privateRun(TestRunner.java:782)
	at org.testng.TestRunner.run(TestRunner.java:632)
	at org.testng.SuiteRunner.runTest(SuiteRunner.java:366)
	at org.testng.SuiteRunner.runSequentially(SuiteRunner.java:361)
	at org.testng.SuiteRunner.privateRun(SuiteRunner.java:319)
	at org.testng.SuiteRunner.run(SuiteRunner.java:268)
	at org.testng.SuiteRunnerWorker.runSuite(SuiteRunnerWorker.java:52)
	at org.testng.SuiteRunnerWorker.run(SuiteRunnerWorker.java:86)
	at org.testng.TestNG.runSuitesSequentially(TestNG.java:1244)
	at org.testng.TestNG.runSuitesLocally(TestNG.java:1169)
	at org.testng.TestNG.run(TestNG.java:1064)
	at org.testng.remote.AbstractRemoteTestNG.run(AbstractRemoteTestNG.java:115)
	at org.testng.remote.RemoteTestNG.initAndRun(RemoteTestNG.java:251)
	at org.testng.remote.RemoteTestNG.main(RemoteTestNG.java:77)
]]>
    </failure>
  </testcase> <!-- Login_process -->
</testsuite> <!-- testcases.EnterCItyName_Testcases -->
